{
 "cells": [
  {
   "cell_type": "code",
   "execution_count": 1,
   "id": "a26322ae",
   "metadata": {},
   "outputs": [],
   "source": [
    "import tensorflow\n",
    "from tensorflow.keras.models import Sequential\n",
    "from keras.layers import  Dense, Conv2D, MaxPooling2D, Flatten,Activation\n",
    "from warnings import filterwarnings\n",
    "filterwarnings('ignore')"
   ]
  },
  {
   "cell_type": "code",
   "execution_count": 2,
   "id": "e65f0761",
   "metadata": {},
   "outputs": [
    {
     "name": "stderr",
     "output_type": "stream",
     "text": [
      "2022-06-01 15:41:14.705561: I tensorflow/stream_executor/cuda/cuda_gpu_executor.cc:939] successful NUMA node read from SysFS had negative value (-1), but there must be at least one NUMA node, so returning NUMA node zero\n"
     ]
    },
    {
     "name": "stdout",
     "output_type": "stream",
     "text": [
      "Model: \"sequential\"\n",
      "_________________________________________________________________\n",
      " Layer (type)                Output Shape              Param #   \n",
      "=================================================================\n",
      " conv2d (Conv2D)             (None, 62, 62, 32)        896       \n",
      "                                                                 \n",
      " max_pooling2d (MaxPooling2D  (None, 31, 31, 32)       0         \n",
      " )                                                               \n",
      "                                                                 \n",
      " conv2d_1 (Conv2D)           (None, 29, 29, 32)        9248      \n",
      "                                                                 \n",
      " max_pooling2d_1 (MaxPooling  (None, 14, 14, 32)       0         \n",
      " 2D)                                                             \n",
      "                                                                 \n",
      " flatten (Flatten)           (None, 6272)              0         \n",
      "                                                                 \n",
      " dense (Dense)               (None, 128)               802944    \n",
      "                                                                 \n",
      " dense_1 (Dense)             (None, 1)                 129       \n",
      "                                                                 \n",
      "=================================================================\n",
      "Total params: 813,217\n",
      "Trainable params: 813,217\n",
      "Non-trainable params: 0\n",
      "_________________________________________________________________\n"
     ]
    },
    {
     "name": "stderr",
     "output_type": "stream",
     "text": [
      "2022-06-01 15:41:14.879701: I tensorflow/stream_executor/cuda/cuda_gpu_executor.cc:939] successful NUMA node read from SysFS had negative value (-1), but there must be at least one NUMA node, so returning NUMA node zero\n",
      "2022-06-01 15:41:14.880096: I tensorflow/stream_executor/cuda/cuda_gpu_executor.cc:939] successful NUMA node read from SysFS had negative value (-1), but there must be at least one NUMA node, so returning NUMA node zero\n",
      "2022-06-01 15:41:14.881675: I tensorflow/core/platform/cpu_feature_guard.cc:151] This TensorFlow binary is optimized with oneAPI Deep Neural Network Library (oneDNN) to use the following CPU instructions in performance-critical operations:  AVX2 FMA\n",
      "To enable them in other operations, rebuild TensorFlow with the appropriate compiler flags.\n",
      "2022-06-01 15:41:14.923800: I tensorflow/stream_executor/cuda/cuda_gpu_executor.cc:939] successful NUMA node read from SysFS had negative value (-1), but there must be at least one NUMA node, so returning NUMA node zero\n",
      "2022-06-01 15:41:14.924564: I tensorflow/stream_executor/cuda/cuda_gpu_executor.cc:939] successful NUMA node read from SysFS had negative value (-1), but there must be at least one NUMA node, so returning NUMA node zero\n",
      "2022-06-01 15:41:14.924918: I tensorflow/stream_executor/cuda/cuda_gpu_executor.cc:939] successful NUMA node read from SysFS had negative value (-1), but there must be at least one NUMA node, so returning NUMA node zero\n",
      "2022-06-01 15:41:16.322710: I tensorflow/stream_executor/cuda/cuda_gpu_executor.cc:939] successful NUMA node read from SysFS had negative value (-1), but there must be at least one NUMA node, so returning NUMA node zero\n",
      "2022-06-01 15:41:16.323002: I tensorflow/stream_executor/cuda/cuda_gpu_executor.cc:939] successful NUMA node read from SysFS had negative value (-1), but there must be at least one NUMA node, so returning NUMA node zero\n",
      "2022-06-01 15:41:16.323201: I tensorflow/stream_executor/cuda/cuda_gpu_executor.cc:939] successful NUMA node read from SysFS had negative value (-1), but there must be at least one NUMA node, so returning NUMA node zero\n",
      "2022-06-01 15:41:16.323377: I tensorflow/core/common_runtime/gpu/gpu_device.cc:1525] Created device /job:localhost/replica:0/task:0/device:GPU:0 with 58 MB memory:  -> device: 0, name: NVIDIA GeForce GTX 1650 Ti, pci bus id: 0000:01:00.0, compute capability: 7.5\n"
     ]
    }
   ],
   "source": [
    "classifier = Sequential()\n",
    "classifier.add(Conv2D(32,(3,3),input_shape=(64,64,3),activation = 'relu'))\n",
    "classifier.add(MaxPooling2D(pool_size=(2,2),strides=2)) #if stride not given it equal to pool filter size\n",
    "classifier.add(Conv2D(32,(3,3),activation = 'relu'))\n",
    "classifier.add(MaxPooling2D(pool_size=(2,2),strides=2))\n",
    "classifier.add(Flatten())\n",
    "classifier.add(Dense(units=128,activation='relu'))\n",
    "classifier.add(Dense(units=1,activation='sigmoid'))\n",
    "adam = tensorflow.keras.optimizers.Adam(lr=0.001, beta_1=0.9, beta_2=0.999, epsilon=None, decay=0.0, amsgrad=False)\n",
    "classifier.compile(optimizer=adam,loss='binary_crossentropy',metrics=['accuracy'])\n",
    "#tensorboard = TensorBoard(log_dir=\"logs/{}\".format(time()))\n",
    "classifier.summary()"
   ]
  },
  {
   "cell_type": "code",
   "execution_count": 5,
   "id": "81c67ac2",
   "metadata": {},
   "outputs": [
    {
     "name": "stdout",
     "output_type": "stream",
     "text": [
      "Found 25000 images belonging to 2 classes.\n",
      "Found 1200 images belonging to 2 classes.\n",
      "Found 12500 images belonging to 1 classes.\n"
     ]
    }
   ],
   "source": [
    "from tensorflow.keras.preprocessing.image import ImageDataGenerator\n",
    "train_datagen = ImageDataGenerator(rescale=1./255,\n",
    "                                   shear_range=0.1,\n",
    "                                   zoom_range=0.1,\n",
    "                                   horizontal_flip=True)\n",
    "test_datagen = ImageDataGenerator(rescale=1./255)\n",
    "\n",
    "#Training Set\n",
    "train_set = train_datagen.flow_from_directory(directory='train/',\n",
    "                                             target_size=(64,64),\n",
    "                                             batch_size=32,\n",
    "                                             class_mode='binary')\n",
    "#Validation Set\n",
    "test_set = test_datagen.flow_from_directory('valid/',\n",
    "                                           target_size=(64,64),\n",
    "                                           batch_size = 32,\n",
    "                                           class_mode='binary',\n",
    "                                           shuffle=False)\n",
    "# Test Set /no output available\n",
    "test_set1 = test_datagen.flow_from_directory(directory='test1/',\n",
    "                                            target_size=(64,64),\n",
    "                                            batch_size=32,\n",
    "                                            shuffle=False)\n",
    "\n"
   ]
  },
  {
   "cell_type": "code",
   "execution_count": 6,
   "id": "4b53e96e",
   "metadata": {},
   "outputs": [
    {
     "name": "stderr",
     "output_type": "stream",
     "text": [
      "2022-06-01 16:18:39.820512: E tensorflow/stream_executor/cuda/cuda_dnn.cc:371] Could not create cudnn handle: CUDNN_STATUS_NOT_INITIALIZED\n",
      "2022-06-01 16:18:39.820904: E tensorflow/stream_executor/cuda/cuda_dnn.cc:379] Possibly insufficient driver version: 515.43.4\n",
      "2022-06-01 16:18:39.827810: W tensorflow/core/framework/op_kernel.cc:1745] OP_REQUIRES failed at conv_ops_fused_impl.h:560 : UNKNOWN: Failed to get convolution algorithm. This is probably because cuDNN failed to initialize, so try looking to see if a warning log message was printed above.\n"
     ]
    },
    {
     "ename": "UnknownError",
     "evalue": " Failed to get convolution algorithm. This is probably because cuDNN failed to initialize, so try looking to see if a warning log message was printed above.\n\t [[node sequential/conv2d/Relu\n (defined at /home/keeibo/anaconda3/envs/env1/lib/python3.8/site-packages/keras/backend.py:4867)\n]] [Op:__inference_train_function_877]\n\nErrors may have originated from an input operation.\nInput Source operations connected to node sequential/conv2d/Relu:\nIn[0] sequential/conv2d/BiasAdd (defined at /home/keeibo/anaconda3/envs/env1/lib/python3.8/site-packages/keras/layers/convolutional.py:264)\n\nOperation defined at: (most recent call last)\n>>>   File \"/home/keeibo/anaconda3/envs/env1/lib/python3.8/runpy.py\", line 194, in _run_module_as_main\n>>>     return _run_code(code, main_globals, None,\n>>> \n>>>   File \"/home/keeibo/anaconda3/envs/env1/lib/python3.8/runpy.py\", line 87, in _run_code\n>>>     exec(code, run_globals)\n>>> \n>>>   File \"/home/keeibo/anaconda3/envs/env1/lib/python3.8/site-packages/ipykernel_launcher.py\", line 16, in <module>\n>>>     app.launch_new_instance()\n>>> \n>>>   File \"/home/keeibo/anaconda3/envs/env1/lib/python3.8/site-packages/traitlets/config/application.py\", line 846, in launch_instance\n>>>     app.start()\n>>> \n>>>   File \"/home/keeibo/anaconda3/envs/env1/lib/python3.8/site-packages/ipykernel/kernelapp.py\", line 677, in start\n>>>     self.io_loop.start()\n>>> \n>>>   File \"/home/keeibo/anaconda3/envs/env1/lib/python3.8/site-packages/tornado/platform/asyncio.py\", line 199, in start\n>>>     self.asyncio_loop.run_forever()\n>>> \n>>>   File \"/home/keeibo/anaconda3/envs/env1/lib/python3.8/asyncio/base_events.py\", line 570, in run_forever\n>>>     self._run_once()\n>>> \n>>>   File \"/home/keeibo/anaconda3/envs/env1/lib/python3.8/asyncio/base_events.py\", line 1859, in _run_once\n>>>     handle._run()\n>>> \n>>>   File \"/home/keeibo/anaconda3/envs/env1/lib/python3.8/asyncio/events.py\", line 81, in _run\n>>>     self._context.run(self._callback, *self._args)\n>>> \n>>>   File \"/home/keeibo/anaconda3/envs/env1/lib/python3.8/site-packages/ipykernel/kernelbase.py\", line 461, in dispatch_queue\n>>>     await self.process_one()\n>>> \n>>>   File \"/home/keeibo/anaconda3/envs/env1/lib/python3.8/site-packages/ipykernel/kernelbase.py\", line 450, in process_one\n>>>     await dispatch(*args)\n>>> \n>>>   File \"/home/keeibo/anaconda3/envs/env1/lib/python3.8/site-packages/ipykernel/kernelbase.py\", line 357, in dispatch_shell\n>>>     await result\n>>> \n>>>   File \"/home/keeibo/anaconda3/envs/env1/lib/python3.8/site-packages/ipykernel/kernelbase.py\", line 652, in execute_request\n>>>     reply_content = await reply_content\n>>> \n>>>   File \"/home/keeibo/anaconda3/envs/env1/lib/python3.8/site-packages/ipykernel/ipkernel.py\", line 359, in do_execute\n>>>     res = shell.run_cell(code, store_history=store_history, silent=silent)\n>>> \n>>>   File \"/home/keeibo/anaconda3/envs/env1/lib/python3.8/site-packages/ipykernel/zmqshell.py\", line 532, in run_cell\n>>>     return super().run_cell(*args, **kwargs)\n>>> \n>>>   File \"/home/keeibo/anaconda3/envs/env1/lib/python3.8/site-packages/IPython/core/interactiveshell.py\", line 2768, in run_cell\n>>>     result = self._run_cell(\n>>> \n>>>   File \"/home/keeibo/anaconda3/envs/env1/lib/python3.8/site-packages/IPython/core/interactiveshell.py\", line 2814, in _run_cell\n>>>     return runner(coro)\n>>> \n>>>   File \"/home/keeibo/anaconda3/envs/env1/lib/python3.8/site-packages/IPython/core/async_helpers.py\", line 129, in _pseudo_sync_runner\n>>>     coro.send(None)\n>>> \n>>>   File \"/home/keeibo/anaconda3/envs/env1/lib/python3.8/site-packages/IPython/core/interactiveshell.py\", line 3012, in run_cell_async\n>>>     has_raised = await self.run_ast_nodes(code_ast.body, cell_name,\n>>> \n>>>   File \"/home/keeibo/anaconda3/envs/env1/lib/python3.8/site-packages/IPython/core/interactiveshell.py\", line 3191, in run_ast_nodes\n>>>     if await self.run_code(code, result, async_=asy):\n>>> \n>>>   File \"/home/keeibo/anaconda3/envs/env1/lib/python3.8/site-packages/IPython/core/interactiveshell.py\", line 3251, in run_code\n>>>     exec(code_obj, self.user_global_ns, self.user_ns)\n>>> \n>>>   File \"/tmp/ipykernel_127386/2085581858.py\", line 1, in <module>\n>>>     get_ipython().run_cell_magic('capture', '', \"classifier.fit_generator(train_set,\\n                        steps_per_epoch=800, \\n                        epochs = 200,\\n                        validation_data = test_set,\\n                        validation_steps = 20, \\n                        #callbacks=[tensorboard]\\n                        );\\n\\n#Some Helpful Instructions:\\n\\n#finetune you network parameter in last by using low learning rate like 0.00001\\n#classifier.save('resources/dogcat_model_bak.h5')\\n#from tensorflow.keras.models import load_model\\n#model = load_model('partial_trained1')\\n#100 iteration with learning rate 0.001 and after that 0.0001\\n\")\n>>> \n>>>   File \"/home/keeibo/anaconda3/envs/env1/lib/python3.8/site-packages/IPython/core/interactiveshell.py\", line 2257, in run_cell_magic\n>>>     result = fn(*args, **kwargs)\n>>> \n>>>   File \"/home/keeibo/anaconda3/envs/env1/lib/python3.8/site-packages/IPython/core/magics/execution.py\", line 1461, in capture\n>>>     self.shell.run_cell(cell)\n>>> \n>>>   File \"/home/keeibo/anaconda3/envs/env1/lib/python3.8/site-packages/ipykernel/zmqshell.py\", line 532, in run_cell\n>>>     return super().run_cell(*args, **kwargs)\n>>> \n>>>   File \"/home/keeibo/anaconda3/envs/env1/lib/python3.8/site-packages/IPython/core/interactiveshell.py\", line 2768, in run_cell\n>>>     result = self._run_cell(\n>>> \n>>>   File \"/home/keeibo/anaconda3/envs/env1/lib/python3.8/site-packages/IPython/core/interactiveshell.py\", line 2814, in _run_cell\n>>>     return runner(coro)\n>>> \n>>>   File \"/home/keeibo/anaconda3/envs/env1/lib/python3.8/site-packages/IPython/core/async_helpers.py\", line 129, in _pseudo_sync_runner\n>>>     coro.send(None)\n>>> \n>>>   File \"/home/keeibo/anaconda3/envs/env1/lib/python3.8/site-packages/IPython/core/interactiveshell.py\", line 3012, in run_cell_async\n>>>     has_raised = await self.run_ast_nodes(code_ast.body, cell_name,\n>>> \n>>>   File \"/home/keeibo/anaconda3/envs/env1/lib/python3.8/site-packages/IPython/core/interactiveshell.py\", line 3191, in run_ast_nodes\n>>>     if await self.run_code(code, result, async_=asy):\n>>> \n>>>   File \"/home/keeibo/anaconda3/envs/env1/lib/python3.8/site-packages/IPython/core/interactiveshell.py\", line 3251, in run_code\n>>>     exec(code_obj, self.user_global_ns, self.user_ns)\n>>> \n>>>   File \"/tmp/ipykernel_127386/3182361028.py\", line 1, in <module>\n>>>     classifier.fit_generator(train_set,\n>>> \n>>>   File \"/home/keeibo/anaconda3/envs/env1/lib/python3.8/site-packages/keras/engine/training.py\", line 2016, in fit_generator\n>>>     return self.fit(\n>>> \n>>>   File \"/home/keeibo/anaconda3/envs/env1/lib/python3.8/site-packages/keras/utils/traceback_utils.py\", line 64, in error_handler\n>>>     return fn(*args, **kwargs)\n>>> \n>>>   File \"/home/keeibo/anaconda3/envs/env1/lib/python3.8/site-packages/keras/engine/training.py\", line 1216, in fit\n>>>     tmp_logs = self.train_function(iterator)\n>>> \n>>>   File \"/home/keeibo/anaconda3/envs/env1/lib/python3.8/site-packages/keras/engine/training.py\", line 878, in train_function\n>>>     return step_function(self, iterator)\n>>> \n>>>   File \"/home/keeibo/anaconda3/envs/env1/lib/python3.8/site-packages/keras/engine/training.py\", line 867, in step_function\n>>>     outputs = model.distribute_strategy.run(run_step, args=(data,))\n>>> \n>>>   File \"/home/keeibo/anaconda3/envs/env1/lib/python3.8/site-packages/keras/engine/training.py\", line 860, in run_step\n>>>     outputs = model.train_step(data)\n>>> \n>>>   File \"/home/keeibo/anaconda3/envs/env1/lib/python3.8/site-packages/keras/engine/training.py\", line 808, in train_step\n>>>     y_pred = self(x, training=True)\n>>> \n>>>   File \"/home/keeibo/anaconda3/envs/env1/lib/python3.8/site-packages/keras/utils/traceback_utils.py\", line 64, in error_handler\n>>>     return fn(*args, **kwargs)\n>>> \n>>>   File \"/home/keeibo/anaconda3/envs/env1/lib/python3.8/site-packages/keras/engine/base_layer.py\", line 1083, in __call__\n>>>     outputs = call_fn(inputs, *args, **kwargs)\n>>> \n>>>   File \"/home/keeibo/anaconda3/envs/env1/lib/python3.8/site-packages/keras/utils/traceback_utils.py\", line 92, in error_handler\n>>>     return fn(*args, **kwargs)\n>>> \n>>>   File \"/home/keeibo/anaconda3/envs/env1/lib/python3.8/site-packages/keras/engine/sequential.py\", line 373, in call\n>>>     return super(Sequential, self).call(inputs, training=training, mask=mask)\n>>> \n>>>   File \"/home/keeibo/anaconda3/envs/env1/lib/python3.8/site-packages/keras/engine/functional.py\", line 451, in call\n>>>     return self._run_internal_graph(\n>>> \n>>>   File \"/home/keeibo/anaconda3/envs/env1/lib/python3.8/site-packages/keras/engine/functional.py\", line 589, in _run_internal_graph\n>>>     outputs = node.layer(*args, **kwargs)\n>>> \n>>>   File \"/home/keeibo/anaconda3/envs/env1/lib/python3.8/site-packages/keras/utils/traceback_utils.py\", line 64, in error_handler\n>>>     return fn(*args, **kwargs)\n>>> \n>>>   File \"/home/keeibo/anaconda3/envs/env1/lib/python3.8/site-packages/keras/engine/base_layer.py\", line 1083, in __call__\n>>>     outputs = call_fn(inputs, *args, **kwargs)\n>>> \n>>>   File \"/home/keeibo/anaconda3/envs/env1/lib/python3.8/site-packages/keras/utils/traceback_utils.py\", line 92, in error_handler\n>>>     return fn(*args, **kwargs)\n>>> \n>>>   File \"/home/keeibo/anaconda3/envs/env1/lib/python3.8/site-packages/keras/layers/convolutional.py\", line 273, in call\n>>>     return self.activation(outputs)\n>>> \n>>>   File \"/home/keeibo/anaconda3/envs/env1/lib/python3.8/site-packages/keras/activations.py\", line 311, in relu\n>>>     return backend.relu(x, alpha=alpha, max_value=max_value, threshold=threshold)\n>>> \n>>>   File \"/home/keeibo/anaconda3/envs/env1/lib/python3.8/site-packages/keras/backend.py\", line 4867, in relu\n>>>     x = tf.nn.relu(x)\n>>> ",
     "output_type": "error",
     "traceback": [
      "\u001b[0;31m---------------------------------------------------------------------------\u001b[0m",
      "\u001b[0;31mUnknownError\u001b[0m                              Traceback (most recent call last)",
      "Input \u001b[0;32mIn [6]\u001b[0m, in \u001b[0;36m<module>\u001b[0;34m\u001b[0m\n\u001b[0;32m----> 1\u001b[0m \u001b[43mclassifier\u001b[49m\u001b[38;5;241;43m.\u001b[39;49m\u001b[43mfit_generator\u001b[49m\u001b[43m(\u001b[49m\u001b[43mtrain_set\u001b[49m\u001b[43m,\u001b[49m\n\u001b[1;32m      2\u001b[0m \u001b[43m                        \u001b[49m\u001b[43msteps_per_epoch\u001b[49m\u001b[38;5;241;43m=\u001b[39;49m\u001b[38;5;241;43m800\u001b[39;49m\u001b[43m,\u001b[49m\u001b[43m \u001b[49m\n\u001b[1;32m      3\u001b[0m \u001b[43m                        \u001b[49m\u001b[43mepochs\u001b[49m\u001b[43m \u001b[49m\u001b[38;5;241;43m=\u001b[39;49m\u001b[43m \u001b[49m\u001b[38;5;241;43m200\u001b[39;49m\u001b[43m,\u001b[49m\n\u001b[1;32m      4\u001b[0m \u001b[43m                        \u001b[49m\u001b[43mvalidation_data\u001b[49m\u001b[43m \u001b[49m\u001b[38;5;241;43m=\u001b[39;49m\u001b[43m \u001b[49m\u001b[43mtest_set\u001b[49m\u001b[43m,\u001b[49m\n\u001b[1;32m      5\u001b[0m \u001b[43m                        \u001b[49m\u001b[43mvalidation_steps\u001b[49m\u001b[43m \u001b[49m\u001b[38;5;241;43m=\u001b[39;49m\u001b[43m \u001b[49m\u001b[38;5;241;43m20\u001b[39;49m\u001b[43m,\u001b[49m\u001b[43m \u001b[49m\n\u001b[1;32m      6\u001b[0m \u001b[43m                        \u001b[49m\u001b[38;5;66;43;03m#callbacks=[tensorboard]\u001b[39;49;00m\n\u001b[1;32m      7\u001b[0m \u001b[43m                        \u001b[49m\u001b[43m)\u001b[49m\n",
      "File \u001b[0;32m~/anaconda3/envs/env1/lib/python3.8/site-packages/keras/engine/training.py:2016\u001b[0m, in \u001b[0;36mModel.fit_generator\u001b[0;34m(self, generator, steps_per_epoch, epochs, verbose, callbacks, validation_data, validation_steps, validation_freq, class_weight, max_queue_size, workers, use_multiprocessing, shuffle, initial_epoch)\u001b[0m\n\u001b[1;32m   2005\u001b[0m \u001b[38;5;124;03m\"\"\"Fits the model on data yielded batch-by-batch by a Python generator.\u001b[39;00m\n\u001b[1;32m   2006\u001b[0m \n\u001b[1;32m   2007\u001b[0m \u001b[38;5;124;03mDEPRECATED:\u001b[39;00m\n\u001b[1;32m   2008\u001b[0m \u001b[38;5;124;03m  `Model.fit` now supports generators, so there is no longer any need to use\u001b[39;00m\n\u001b[1;32m   2009\u001b[0m \u001b[38;5;124;03m  this endpoint.\u001b[39;00m\n\u001b[1;32m   2010\u001b[0m \u001b[38;5;124;03m\"\"\"\u001b[39;00m\n\u001b[1;32m   2011\u001b[0m warnings\u001b[38;5;241m.\u001b[39mwarn(\n\u001b[1;32m   2012\u001b[0m     \u001b[38;5;124m'\u001b[39m\u001b[38;5;124m`Model.fit_generator` is deprecated and \u001b[39m\u001b[38;5;124m'\u001b[39m\n\u001b[1;32m   2013\u001b[0m     \u001b[38;5;124m'\u001b[39m\u001b[38;5;124mwill be removed in a future version. \u001b[39m\u001b[38;5;124m'\u001b[39m\n\u001b[1;32m   2014\u001b[0m     \u001b[38;5;124m'\u001b[39m\u001b[38;5;124mPlease use `Model.fit`, which supports generators.\u001b[39m\u001b[38;5;124m'\u001b[39m,\n\u001b[1;32m   2015\u001b[0m     stacklevel\u001b[38;5;241m=\u001b[39m\u001b[38;5;241m2\u001b[39m)\n\u001b[0;32m-> 2016\u001b[0m \u001b[38;5;28;01mreturn\u001b[39;00m \u001b[38;5;28;43mself\u001b[39;49m\u001b[38;5;241;43m.\u001b[39;49m\u001b[43mfit\u001b[49m\u001b[43m(\u001b[49m\n\u001b[1;32m   2017\u001b[0m \u001b[43m    \u001b[49m\u001b[43mgenerator\u001b[49m\u001b[43m,\u001b[49m\n\u001b[1;32m   2018\u001b[0m \u001b[43m    \u001b[49m\u001b[43msteps_per_epoch\u001b[49m\u001b[38;5;241;43m=\u001b[39;49m\u001b[43msteps_per_epoch\u001b[49m\u001b[43m,\u001b[49m\n\u001b[1;32m   2019\u001b[0m \u001b[43m    \u001b[49m\u001b[43mepochs\u001b[49m\u001b[38;5;241;43m=\u001b[39;49m\u001b[43mepochs\u001b[49m\u001b[43m,\u001b[49m\n\u001b[1;32m   2020\u001b[0m \u001b[43m    \u001b[49m\u001b[43mverbose\u001b[49m\u001b[38;5;241;43m=\u001b[39;49m\u001b[43mverbose\u001b[49m\u001b[43m,\u001b[49m\n\u001b[1;32m   2021\u001b[0m \u001b[43m    \u001b[49m\u001b[43mcallbacks\u001b[49m\u001b[38;5;241;43m=\u001b[39;49m\u001b[43mcallbacks\u001b[49m\u001b[43m,\u001b[49m\n\u001b[1;32m   2022\u001b[0m \u001b[43m    \u001b[49m\u001b[43mvalidation_data\u001b[49m\u001b[38;5;241;43m=\u001b[39;49m\u001b[43mvalidation_data\u001b[49m\u001b[43m,\u001b[49m\n\u001b[1;32m   2023\u001b[0m \u001b[43m    \u001b[49m\u001b[43mvalidation_steps\u001b[49m\u001b[38;5;241;43m=\u001b[39;49m\u001b[43mvalidation_steps\u001b[49m\u001b[43m,\u001b[49m\n\u001b[1;32m   2024\u001b[0m \u001b[43m    \u001b[49m\u001b[43mvalidation_freq\u001b[49m\u001b[38;5;241;43m=\u001b[39;49m\u001b[43mvalidation_freq\u001b[49m\u001b[43m,\u001b[49m\n\u001b[1;32m   2025\u001b[0m \u001b[43m    \u001b[49m\u001b[43mclass_weight\u001b[49m\u001b[38;5;241;43m=\u001b[39;49m\u001b[43mclass_weight\u001b[49m\u001b[43m,\u001b[49m\n\u001b[1;32m   2026\u001b[0m \u001b[43m    \u001b[49m\u001b[43mmax_queue_size\u001b[49m\u001b[38;5;241;43m=\u001b[39;49m\u001b[43mmax_queue_size\u001b[49m\u001b[43m,\u001b[49m\n\u001b[1;32m   2027\u001b[0m \u001b[43m    \u001b[49m\u001b[43mworkers\u001b[49m\u001b[38;5;241;43m=\u001b[39;49m\u001b[43mworkers\u001b[49m\u001b[43m,\u001b[49m\n\u001b[1;32m   2028\u001b[0m \u001b[43m    \u001b[49m\u001b[43muse_multiprocessing\u001b[49m\u001b[38;5;241;43m=\u001b[39;49m\u001b[43muse_multiprocessing\u001b[49m\u001b[43m,\u001b[49m\n\u001b[1;32m   2029\u001b[0m \u001b[43m    \u001b[49m\u001b[43mshuffle\u001b[49m\u001b[38;5;241;43m=\u001b[39;49m\u001b[43mshuffle\u001b[49m\u001b[43m,\u001b[49m\n\u001b[1;32m   2030\u001b[0m \u001b[43m    \u001b[49m\u001b[43minitial_epoch\u001b[49m\u001b[38;5;241;43m=\u001b[39;49m\u001b[43minitial_epoch\u001b[49m\u001b[43m)\u001b[49m\n",
      "File \u001b[0;32m~/anaconda3/envs/env1/lib/python3.8/site-packages/keras/utils/traceback_utils.py:67\u001b[0m, in \u001b[0;36mfilter_traceback.<locals>.error_handler\u001b[0;34m(*args, **kwargs)\u001b[0m\n\u001b[1;32m     65\u001b[0m \u001b[38;5;28;01mexcept\u001b[39;00m \u001b[38;5;167;01mException\u001b[39;00m \u001b[38;5;28;01mas\u001b[39;00m e:  \u001b[38;5;66;03m# pylint: disable=broad-except\u001b[39;00m\n\u001b[1;32m     66\u001b[0m   filtered_tb \u001b[38;5;241m=\u001b[39m _process_traceback_frames(e\u001b[38;5;241m.\u001b[39m__traceback__)\n\u001b[0;32m---> 67\u001b[0m   \u001b[38;5;28;01mraise\u001b[39;00m e\u001b[38;5;241m.\u001b[39mwith_traceback(filtered_tb) \u001b[38;5;28;01mfrom\u001b[39;00m \u001b[38;5;28mNone\u001b[39m\n\u001b[1;32m     68\u001b[0m \u001b[38;5;28;01mfinally\u001b[39;00m:\n\u001b[1;32m     69\u001b[0m   \u001b[38;5;28;01mdel\u001b[39;00m filtered_tb\n",
      "File \u001b[0;32m~/anaconda3/envs/env1/lib/python3.8/site-packages/tensorflow/python/eager/execute.py:58\u001b[0m, in \u001b[0;36mquick_execute\u001b[0;34m(op_name, num_outputs, inputs, attrs, ctx, name)\u001b[0m\n\u001b[1;32m     56\u001b[0m \u001b[38;5;28;01mtry\u001b[39;00m:\n\u001b[1;32m     57\u001b[0m   ctx\u001b[38;5;241m.\u001b[39mensure_initialized()\n\u001b[0;32m---> 58\u001b[0m   tensors \u001b[38;5;241m=\u001b[39m pywrap_tfe\u001b[38;5;241m.\u001b[39mTFE_Py_Execute(ctx\u001b[38;5;241m.\u001b[39m_handle, device_name, op_name,\n\u001b[1;32m     59\u001b[0m                                       inputs, attrs, num_outputs)\n\u001b[1;32m     60\u001b[0m \u001b[38;5;28;01mexcept\u001b[39;00m core\u001b[38;5;241m.\u001b[39m_NotOkStatusException \u001b[38;5;28;01mas\u001b[39;00m e:\n\u001b[1;32m     61\u001b[0m   \u001b[38;5;28;01mif\u001b[39;00m name \u001b[38;5;129;01mis\u001b[39;00m \u001b[38;5;129;01mnot\u001b[39;00m \u001b[38;5;28;01mNone\u001b[39;00m:\n",
      "\u001b[0;31mUnknownError\u001b[0m:  Failed to get convolution algorithm. This is probably because cuDNN failed to initialize, so try looking to see if a warning log message was printed above.\n\t [[node sequential/conv2d/Relu\n (defined at /home/keeibo/anaconda3/envs/env1/lib/python3.8/site-packages/keras/backend.py:4867)\n]] [Op:__inference_train_function_877]\n\nErrors may have originated from an input operation.\nInput Source operations connected to node sequential/conv2d/Relu:\nIn[0] sequential/conv2d/BiasAdd (defined at /home/keeibo/anaconda3/envs/env1/lib/python3.8/site-packages/keras/layers/convolutional.py:264)\n\nOperation defined at: (most recent call last)\n>>>   File \"/home/keeibo/anaconda3/envs/env1/lib/python3.8/runpy.py\", line 194, in _run_module_as_main\n>>>     return _run_code(code, main_globals, None,\n>>> \n>>>   File \"/home/keeibo/anaconda3/envs/env1/lib/python3.8/runpy.py\", line 87, in _run_code\n>>>     exec(code, run_globals)\n>>> \n>>>   File \"/home/keeibo/anaconda3/envs/env1/lib/python3.8/site-packages/ipykernel_launcher.py\", line 16, in <module>\n>>>     app.launch_new_instance()\n>>> \n>>>   File \"/home/keeibo/anaconda3/envs/env1/lib/python3.8/site-packages/traitlets/config/application.py\", line 846, in launch_instance\n>>>     app.start()\n>>> \n>>>   File \"/home/keeibo/anaconda3/envs/env1/lib/python3.8/site-packages/ipykernel/kernelapp.py\", line 677, in start\n>>>     self.io_loop.start()\n>>> \n>>>   File \"/home/keeibo/anaconda3/envs/env1/lib/python3.8/site-packages/tornado/platform/asyncio.py\", line 199, in start\n>>>     self.asyncio_loop.run_forever()\n>>> \n>>>   File \"/home/keeibo/anaconda3/envs/env1/lib/python3.8/asyncio/base_events.py\", line 570, in run_forever\n>>>     self._run_once()\n>>> \n>>>   File \"/home/keeibo/anaconda3/envs/env1/lib/python3.8/asyncio/base_events.py\", line 1859, in _run_once\n>>>     handle._run()\n>>> \n>>>   File \"/home/keeibo/anaconda3/envs/env1/lib/python3.8/asyncio/events.py\", line 81, in _run\n>>>     self._context.run(self._callback, *self._args)\n>>> \n>>>   File \"/home/keeibo/anaconda3/envs/env1/lib/python3.8/site-packages/ipykernel/kernelbase.py\", line 461, in dispatch_queue\n>>>     await self.process_one()\n>>> \n>>>   File \"/home/keeibo/anaconda3/envs/env1/lib/python3.8/site-packages/ipykernel/kernelbase.py\", line 450, in process_one\n>>>     await dispatch(*args)\n>>> \n>>>   File \"/home/keeibo/anaconda3/envs/env1/lib/python3.8/site-packages/ipykernel/kernelbase.py\", line 357, in dispatch_shell\n>>>     await result\n>>> \n>>>   File \"/home/keeibo/anaconda3/envs/env1/lib/python3.8/site-packages/ipykernel/kernelbase.py\", line 652, in execute_request\n>>>     reply_content = await reply_content\n>>> \n>>>   File \"/home/keeibo/anaconda3/envs/env1/lib/python3.8/site-packages/ipykernel/ipkernel.py\", line 359, in do_execute\n>>>     res = shell.run_cell(code, store_history=store_history, silent=silent)\n>>> \n>>>   File \"/home/keeibo/anaconda3/envs/env1/lib/python3.8/site-packages/ipykernel/zmqshell.py\", line 532, in run_cell\n>>>     return super().run_cell(*args, **kwargs)\n>>> \n>>>   File \"/home/keeibo/anaconda3/envs/env1/lib/python3.8/site-packages/IPython/core/interactiveshell.py\", line 2768, in run_cell\n>>>     result = self._run_cell(\n>>> \n>>>   File \"/home/keeibo/anaconda3/envs/env1/lib/python3.8/site-packages/IPython/core/interactiveshell.py\", line 2814, in _run_cell\n>>>     return runner(coro)\n>>> \n>>>   File \"/home/keeibo/anaconda3/envs/env1/lib/python3.8/site-packages/IPython/core/async_helpers.py\", line 129, in _pseudo_sync_runner\n>>>     coro.send(None)\n>>> \n>>>   File \"/home/keeibo/anaconda3/envs/env1/lib/python3.8/site-packages/IPython/core/interactiveshell.py\", line 3012, in run_cell_async\n>>>     has_raised = await self.run_ast_nodes(code_ast.body, cell_name,\n>>> \n>>>   File \"/home/keeibo/anaconda3/envs/env1/lib/python3.8/site-packages/IPython/core/interactiveshell.py\", line 3191, in run_ast_nodes\n>>>     if await self.run_code(code, result, async_=asy):\n>>> \n>>>   File \"/home/keeibo/anaconda3/envs/env1/lib/python3.8/site-packages/IPython/core/interactiveshell.py\", line 3251, in run_code\n>>>     exec(code_obj, self.user_global_ns, self.user_ns)\n>>> \n>>>   File \"/tmp/ipykernel_127386/2085581858.py\", line 1, in <module>\n>>>     get_ipython().run_cell_magic('capture', '', \"classifier.fit_generator(train_set,\\n                        steps_per_epoch=800, \\n                        epochs = 200,\\n                        validation_data = test_set,\\n                        validation_steps = 20, \\n                        #callbacks=[tensorboard]\\n                        );\\n\\n#Some Helpful Instructions:\\n\\n#finetune you network parameter in last by using low learning rate like 0.00001\\n#classifier.save('resources/dogcat_model_bak.h5')\\n#from tensorflow.keras.models import load_model\\n#model = load_model('partial_trained1')\\n#100 iteration with learning rate 0.001 and after that 0.0001\\n\")\n>>> \n>>>   File \"/home/keeibo/anaconda3/envs/env1/lib/python3.8/site-packages/IPython/core/interactiveshell.py\", line 2257, in run_cell_magic\n>>>     result = fn(*args, **kwargs)\n>>> \n>>>   File \"/home/keeibo/anaconda3/envs/env1/lib/python3.8/site-packages/IPython/core/magics/execution.py\", line 1461, in capture\n>>>     self.shell.run_cell(cell)\n>>> \n>>>   File \"/home/keeibo/anaconda3/envs/env1/lib/python3.8/site-packages/ipykernel/zmqshell.py\", line 532, in run_cell\n>>>     return super().run_cell(*args, **kwargs)\n>>> \n>>>   File \"/home/keeibo/anaconda3/envs/env1/lib/python3.8/site-packages/IPython/core/interactiveshell.py\", line 2768, in run_cell\n>>>     result = self._run_cell(\n>>> \n>>>   File \"/home/keeibo/anaconda3/envs/env1/lib/python3.8/site-packages/IPython/core/interactiveshell.py\", line 2814, in _run_cell\n>>>     return runner(coro)\n>>> \n>>>   File \"/home/keeibo/anaconda3/envs/env1/lib/python3.8/site-packages/IPython/core/async_helpers.py\", line 129, in _pseudo_sync_runner\n>>>     coro.send(None)\n>>> \n>>>   File \"/home/keeibo/anaconda3/envs/env1/lib/python3.8/site-packages/IPython/core/interactiveshell.py\", line 3012, in run_cell_async\n>>>     has_raised = await self.run_ast_nodes(code_ast.body, cell_name,\n>>> \n>>>   File \"/home/keeibo/anaconda3/envs/env1/lib/python3.8/site-packages/IPython/core/interactiveshell.py\", line 3191, in run_ast_nodes\n>>>     if await self.run_code(code, result, async_=asy):\n>>> \n>>>   File \"/home/keeibo/anaconda3/envs/env1/lib/python3.8/site-packages/IPython/core/interactiveshell.py\", line 3251, in run_code\n>>>     exec(code_obj, self.user_global_ns, self.user_ns)\n>>> \n>>>   File \"/tmp/ipykernel_127386/3182361028.py\", line 1, in <module>\n>>>     classifier.fit_generator(train_set,\n>>> \n>>>   File \"/home/keeibo/anaconda3/envs/env1/lib/python3.8/site-packages/keras/engine/training.py\", line 2016, in fit_generator\n>>>     return self.fit(\n>>> \n>>>   File \"/home/keeibo/anaconda3/envs/env1/lib/python3.8/site-packages/keras/utils/traceback_utils.py\", line 64, in error_handler\n>>>     return fn(*args, **kwargs)\n>>> \n>>>   File \"/home/keeibo/anaconda3/envs/env1/lib/python3.8/site-packages/keras/engine/training.py\", line 1216, in fit\n>>>     tmp_logs = self.train_function(iterator)\n>>> \n>>>   File \"/home/keeibo/anaconda3/envs/env1/lib/python3.8/site-packages/keras/engine/training.py\", line 878, in train_function\n>>>     return step_function(self, iterator)\n>>> \n>>>   File \"/home/keeibo/anaconda3/envs/env1/lib/python3.8/site-packages/keras/engine/training.py\", line 867, in step_function\n>>>     outputs = model.distribute_strategy.run(run_step, args=(data,))\n>>> \n>>>   File \"/home/keeibo/anaconda3/envs/env1/lib/python3.8/site-packages/keras/engine/training.py\", line 860, in run_step\n>>>     outputs = model.train_step(data)\n>>> \n>>>   File \"/home/keeibo/anaconda3/envs/env1/lib/python3.8/site-packages/keras/engine/training.py\", line 808, in train_step\n>>>     y_pred = self(x, training=True)\n>>> \n>>>   File \"/home/keeibo/anaconda3/envs/env1/lib/python3.8/site-packages/keras/utils/traceback_utils.py\", line 64, in error_handler\n>>>     return fn(*args, **kwargs)\n>>> \n>>>   File \"/home/keeibo/anaconda3/envs/env1/lib/python3.8/site-packages/keras/engine/base_layer.py\", line 1083, in __call__\n>>>     outputs = call_fn(inputs, *args, **kwargs)\n>>> \n>>>   File \"/home/keeibo/anaconda3/envs/env1/lib/python3.8/site-packages/keras/utils/traceback_utils.py\", line 92, in error_handler\n>>>     return fn(*args, **kwargs)\n>>> \n>>>   File \"/home/keeibo/anaconda3/envs/env1/lib/python3.8/site-packages/keras/engine/sequential.py\", line 373, in call\n>>>     return super(Sequential, self).call(inputs, training=training, mask=mask)\n>>> \n>>>   File \"/home/keeibo/anaconda3/envs/env1/lib/python3.8/site-packages/keras/engine/functional.py\", line 451, in call\n>>>     return self._run_internal_graph(\n>>> \n>>>   File \"/home/keeibo/anaconda3/envs/env1/lib/python3.8/site-packages/keras/engine/functional.py\", line 589, in _run_internal_graph\n>>>     outputs = node.layer(*args, **kwargs)\n>>> \n>>>   File \"/home/keeibo/anaconda3/envs/env1/lib/python3.8/site-packages/keras/utils/traceback_utils.py\", line 64, in error_handler\n>>>     return fn(*args, **kwargs)\n>>> \n>>>   File \"/home/keeibo/anaconda3/envs/env1/lib/python3.8/site-packages/keras/engine/base_layer.py\", line 1083, in __call__\n>>>     outputs = call_fn(inputs, *args, **kwargs)\n>>> \n>>>   File \"/home/keeibo/anaconda3/envs/env1/lib/python3.8/site-packages/keras/utils/traceback_utils.py\", line 92, in error_handler\n>>>     return fn(*args, **kwargs)\n>>> \n>>>   File \"/home/keeibo/anaconda3/envs/env1/lib/python3.8/site-packages/keras/layers/convolutional.py\", line 273, in call\n>>>     return self.activation(outputs)\n>>> \n>>>   File \"/home/keeibo/anaconda3/envs/env1/lib/python3.8/site-packages/keras/activations.py\", line 311, in relu\n>>>     return backend.relu(x, alpha=alpha, max_value=max_value, threshold=threshold)\n>>> \n>>>   File \"/home/keeibo/anaconda3/envs/env1/lib/python3.8/site-packages/keras/backend.py\", line 4867, in relu\n>>>     x = tf.nn.relu(x)\n>>> "
     ]
    }
   ],
   "source": [
    "%%capture\n",
    "classifier.fit_generator(train_set,\n",
    "                        steps_per_epoch=800, \n",
    "                        epochs = 200,\n",
    "                        validation_data = test_set,\n",
    "                        validation_steps = 20, \n",
    "                        #callbacks=[tensorboard]\n",
    "                        );\n",
    "\n",
    "#Some Helpful Instructions:\n",
    "\n",
    "#finetune you network parameter in last by using low learning rate like 0.00001\n",
    "#classifier.save('resources/dogcat_model_bak.h5')\n",
    "#from tensorflow.keras.models import load_model\n",
    "#model = load_model('partial_trained1')\n",
    "#100 iteration with learning rate 0.001 and after that 0.0001"
   ]
  },
  {
   "cell_type": "code",
   "execution_count": null,
   "id": "41985013",
   "metadata": {},
   "outputs": [],
   "source": []
  }
 ],
 "metadata": {
  "kernelspec": {
   "display_name": "Python 3 (ipykernel)",
   "language": "python",
   "name": "python3"
  },
  "language_info": {
   "codemirror_mode": {
    "name": "ipython",
    "version": 3
   },
   "file_extension": ".py",
   "mimetype": "text/x-python",
   "name": "python",
   "nbconvert_exporter": "python",
   "pygments_lexer": "ipython3",
   "version": "3.8.12"
  }
 },
 "nbformat": 4,
 "nbformat_minor": 5
}
